<sdf version='1.6'>
  <world name='default'>
    <light name='sun' type='directional'>
      <cast_shadows>1</cast_shadows>
      <pose frame=''>0 0 10 0 -0 0</pose>
      <diffuse>0.8 0.8 0.8 1</diffuse>
      <specular>0.2 0.2 0.2 1</specular>
      <attenuation>
        <range>1000</range>
        <constant>0.9</constant>
        <linear>0.01</linear>
        <quadratic>0.001</quadratic>
      </attenuation>
      <direction>-0.5 0.1 -0.9</direction>
    </light>
    <model name='ground_plane'>
      <static>1</static>
      <link name='link'>
        <collision name='collision'>
          <geometry>
            <plane>
              <normal>0 0 1</normal>
              <size>100 100</size>
            </plane>
          </geometry>
          <surface>
            <friction>
              <ode>
                <mu>100</mu>
                <mu2>50</mu2>
              </ode>
              <torsional>
                <ode/>
              </torsional>
            </friction>
            <contact>
              <ode/>
            </contact>
            <bounce/>
          </surface>
          <max_contacts>10</max_contacts>
        </collision>
        <visual name='visual'>
          <cast_shadows>0</cast_shadows>
          <geometry>
            <plane>
              <normal>0 0 1</normal>
              <size>100 100</size>
            </plane>
          </geometry>
          <material>
            <script>
              <uri>file://media/materials/scripts/gazebo.material</uri>
              <name>Gazebo/Grey</name>
            </script>
          </material>
        </visual>
        <self_collide>0</self_collide>
        <kinematic>0</kinematic>
      </link>
    </model>
    <gravity>0 0 -9.8</gravity>
    <magnetic_field>6e-06 2.3e-05 -4.2e-05</magnetic_field>
    <atmosphere type='adiabatic'/>
    <physics name='default_physics' default='0' type='ode'>
      <max_step_size>0.001</max_step_size>
      <real_time_factor>1</real_time_factor>
      <real_time_update_rate>1000</real_time_update_rate>
    </physics>
    <scene>
      <ambient>0.4 0.4 0.4 1</ambient>
      <background>0.7 0.7 0.7 1</background>
      <shadows>1</shadows>
    </scene>
    <spherical_coordinates>
      <surface_model>EARTH_WGS84</surface_model>
      <latitude_deg>0</latitude_deg>
      <longitude_deg>0</longitude_deg>
      <elevation>0</elevation>
      <heading_deg>0</heading_deg>
    </spherical_coordinates>
    <model name='double_pendulum_with_base'>
      <link name='base'>
        <inertial>
          <mass>100</mass>
          <inertia>
            <ixx>1</ixx>
            <ixy>0</ixy>
            <ixz>0</ixz>
            <iyy>1</iyy>
            <iyz>0</iyz>
            <izz>1</izz>
          </inertia>
        </inertial>
        <visual name='vis_plate_on_ground'>
          <pose frame=''>0 0 0.01 0 -0 0</pose>
          <geometry>
            <cylinder>
              <radius>0.8</radius>
              <length>0.02</length>
            </cylinder>
          </geometry>
          <material>
            <script>
              <uri>file://media/materials/scripts/gazebo.material</uri>
              <name>Gazebo/Grey</name>
            </script>
          </material>
        </visual>
        <visual name='vis_pole'>
          <pose frame=''>-0.275 0 1.1 0 -0 0</pose>
          <geometry>
            <box>
              <size>0.2 0.2 2.2</size>
            </box>
          </geometry>
          <material>
            <script>
              <uri>file://media/materials/scripts/gazebo.material</uri>
              <name>Gazebo/Grey</name>
            </script>
          </material>
        </visual>
        <collision name='col_plate_on_ground'>
          <pose frame=''>0 0 0.01 0 -0 0</pose>
          <geometry>
            <cylinder>
              <radius>0.8</radius>
              <length>0.02</length>
            </cylinder>
          </geometry>
          <max_contacts>10</max_contacts>
          <surface>
            <contact>
              <ode/>
            </contact>
            <bounce/>
            <friction>
              <torsional>
                <ode/>
              </torsional>
              <ode/>
            </friction>
          </surface>
        </collision>
        <collision name='col_pole'>
          <pose frame=''>-0.275 0 1.1 0 -0 0</pose>
          <geometry>
            <box>
              <size>0.2 0.2 2.2</size>
            </box>
          </geometry>
          <max_contacts>10</max_contacts>
          <surface>
            <contact>
              <ode/>
            </contact>
            <bounce/>
            <friction>
              <torsional>
                <ode/>
              </torsional>
              <ode/>
            </friction>
          </surface>
        </collision>
        <self_collide>0</self_collide>
        <kinematic>0</kinematic>
      </link>
      <link name='upper_link'>
        <pose frame=''>0 0 2.1 -1.5708 0 0</pose>
        <self_collide>0</self_collide>
        <inertial>
          <pose frame=''>0 0 0.5 0 -0 0</pose>
          <inertia>
            <ixx>1</ixx>
            <ixy>0</ixy>
            <ixz>0</ixz>
            <iyy>1</iyy>
            <iyz>0</iyz>
            <izz>1</izz>
          </inertia>
          <mass>1</mass>
        </inertial>
        <visual name='vis_upper_joint'>
          <pose frame=''>-0.05 0 0 3.14159 1.57079 3.14159</pose>
          <geometry>
            <cylinder>
              <radius>0.1</radius>
              <length>0.3</length>
            </cylinder>
          </geometry>
          <material>
            <script>
              <uri>file://media/materials/scripts/gazebo.material</uri>
              <name>Gazebo/Grey</name>
            </script>
          </material>
        </visual>
        <visual name='vis_lower_joint'>
          <pose frame=''>0 0 1 3.14159 1.57079 3.14159</pose>
          <geometry>
            <cylinder>
              <radius>0.1</radius>
              <length>0.2</length>
            </cylinder>
          </geometry>
          <material>
            <script>
              <uri>file://media/materials/scripts/gazebo.material</uri>
              <name>Gazebo/Grey</name>
            </script>
          </material>
        </visual>
        <visual name='vis_cylinder'>
          <pose frame=''>0 0 0.5 0 -0 0</pose>
          <geometry>
            <cylinder>
              <radius>0.1</radius>
              <length>0.9</length>
            </cylinder>
          </geometry>
          <material>
            <script>
              <uri>file://media/materials/scripts/gazebo.material</uri>
              <name>Gazebo/Grey</name>
            </script>
          </material>
        </visual>
        <collision name='col_upper_joint'>
          <pose frame=''>-0.05 0 0 3.14159 1.57079 3.14159</pose>
          <geometry>
            <cylinder>
              <radius>0.1</radius>
              <length>0.3</length>
            </cylinder>
          </geometry>
          <max_contacts>10</max_contacts>
          <surface>
            <contact>
              <ode/>
            </contact>
            <bounce/>
            <friction>
              <torsional>
                <ode/>
              </torsional>
              <ode/>
            </friction>
          </surface>
        </collision>
        <collision name='col_lower_joint'>
          <pose frame=''>0 0 1 3.14159 1.57079 3.14159</pose>
          <geometry>
            <cylinder>
              <radius>0.1</radius>
              <length>0.2</length>
            </cylinder>
          </geometry>
          <max_contacts>10</max_contacts>
          <surface>
            <contact>
              <ode/>
            </contact>
            <bounce/>
            <friction>
              <torsional>
                <ode/>
              </torsional>
              <ode/>
            </friction>
          </surface>
        </collision>
        <collision name='col_cylinder'>
          <pose frame=''>0 0 0.5 0 -0 0</pose>
          <geometry>
            <cylinder>
              <radius>0.1</radius>
              <length>0.9</length>
            </cylinder>
          </geometry>
          <max_contacts>10</max_contacts>
          <surface>
            <contact>
              <ode/>
            </contact>
            <bounce/>
            <friction>
              <torsional>
                <ode/>
              </torsional>
              <ode/>
            </friction>
          </surface>
        </collision>
        <kinematic>0</kinematic>
      </link>
      <link name='lower_link'>
        <pose frame=''>0.25 1 2.1 -2 0 0</pose>
        <self_collide>0</self_collide>
        <inertial>
          <pose frame=''>0 0 0.5 0 -0 0</pose>
          <inertia>
            <ixx>1</ixx>
            <ixy>0</ixy>
            <ixz>0</ixz>
            <iyy>1</iyy>
            <iyz>0</iyz>
            <izz>1</izz>
          </inertia>
          <mass>1</mass>
        </inertial>
        <visual name='vis_lower_joint'>
          <pose frame=''>0 0 0 3.14159 1.57079 3.14159</pose>
          <geometry>
            <cylinder>
              <radius>0.08</radius>
              <length>0.3</length>
            </cylinder>
          </geometry>
          <material>
            <script>
              <uri>file://media/materials/scripts/gazebo.material</uri>
              <name>Gazebo/Grey</name>
            </script>
          </material>
        </visual>
        <visual name='vis_cylinder'>
          <pose frame=''>0 0 0.5 0 -0 0</pose>
          <geometry>
            <cylinder>
              <radius>0.1</radius>
              <length>0.9</length>
            </cylinder>
          </geometry>
          <material>
            <script>
              <uri>file://media/materials/scripts/gazebo.material</uri>
              <name>Gazebo/Grey</name>
            </script>
          </material>
        </visual>
        <collision name='col_lower_joint'>
          <pose frame=''>0 0 0 3.14159 1.57079 3.14159</pose>
          <geometry>
            <cylinder>
              <radius>0.08</radius>
              <length>0.3</length>
            </cylinder>
          </geometry>
          <max_contacts>10</max_contacts>
          <surface>
            <contact>
              <ode/>
            </contact>
            <bounce/>
            <friction>
              <torsional>
                <ode/>
              </torsional>
              <ode/>
            </friction>
          </surface>
        </collision>
        <collision name='col_cylinder'>
          <pose frame=''>0 0 0.5 0 -0 0</pose>
          <geometry>
            <cylinder>
              <radius>0.1</radius>
              <length>0.9</length>
            </cylinder>
          </geometry>
          <max_contacts>10</max_contacts>
          <surface>
            <contact>
              <ode/>
            </contact>
            <bounce/>
            <friction>
              <torsional>
                <ode/>
              </torsional>
              <ode/>
            </friction>
          </surface>
        </collision>
        <kinematic>0</kinematic>
      </link>
      <joint name='upper_joint' type='revolute'>
        <parent>base</parent>
        <child>upper_link</child>
        <axis>
          <xyz>1 0 0</xyz>
          <use_parent_model_frame>1</use_parent_model_frame>
          <limit>
            <lower>-1e+16</lower>
            <upper>1e+16</upper>
          </limit>
          <dynamics>
            <spring_reference>0</spring_reference>
            <spring_stiffness>0</spring_stiffness>
          </dynamics>
        </axis>
      </joint>
      <joint name='lower_joint' type='revolute'>
        <parent>upper_link</parent>
        <child>lower_link</child>
        <axis>
          <xyz>1 0 0</xyz>
          <use_parent_model_frame>1</use_parent_model_frame>
          <limit>
            <lower>-1e+16</lower>
            <upper>1e+16</upper>
          </limit>
          <dynamics>
            <spring_reference>0</spring_reference>
            <spring_stiffness>0</spring_stiffness>
          </dynamics>
        </axis>
      </joint>
      <pose frame=''>5.00459 0.118802 0 0 -0 0</pose>
    </model>
    <state world_name='default'>
      <sim_time>41 356000000</sim_time>
      <real_time>41 608706847</real_time>
      <wall_time>1491789877 623185029</wall_time>
      <iterations>41356</iterations>
      <model name='double_pendulum_with_base'>
        <pose frame=''>5.0045 0.118729 -0 0 -0 -0.000489</pose>
        <scale>1 1 1</scale>
        <link name='base'>
          <pose frame=''>5.0045 0.118729 -0 0 -0 -0.000489</pose>
          <velocity>-0 0 0.008851 0.001703 0.005885 0</velocity>
          <acceleration>0.007612 -0.00643 17.5991 2.91699 0.050585 -0.026876</acceleration>
          <wrench>0.761191 -0.642968 1759.91 0 -0 0</wrench>
        </link>
        <link name='lower_link'>
          <pose frame=''>5.25473 0.579594 1.21257 2.36356 0 -0.000489</pose>
          <velocity>0.00505 -2.55332 -1.3227 -3.03054 0.003228 9.9e-05</velocity>
          <acceleration>10.4738 -8.19842 17.8293 0.076125 -0.908157 0.061939</acceleration>
          <wrench>10.4738 -8.19842 17.8293 0 -0 0</wrench>
        </link>
        <link name='upper_link'>
          <pose frame=''>5.0045 0.118734 2.09999 -2.66249 -0 -0.000489</pose>
          <velocity>0.010998 -0.002532 0.006963 -2.87344 0.006379 3.6e-05</velocity>
          <acceleration>20.0616 -11.2458 19.5303 -1.07799 -0.760393 -0.00049</acceleration>
          <wrench>20.0616 -11.2458 19.5303 0 -0 0</wrench>
        </link>
      </model>
      <model name='ground_plane'>
        <pose frame=''>0 0 0 0 -0 0</pose>
        <scale>1 1 1</scale>
        <link name='link'>
          <pose frame=''>0 0 0 0 -0 0</pose>
          <velocity>0 0 0 0 -0 0</velocity>
          <acceleration>0 0 0 0 -0 0</acceleration>
          <wrench>0 0 0 0 -0 0</wrench>
        </link>
      </model>
      <light name='sun'>
        <pose frame=''>0 0 10 0 -0 0</pose>
      </light>
    </state>
    <gui fullscreen='0'>
      <camera name='user_camera'>
        <pose frame=''>9.88212 -8.6227 3.52029 0 0.275643 2.35619</pose>
        <view_controller>orbit</view_controller>
        <projection_type>perspective</projection_type>
      </camera>
    </gui>
  </world>
</sdf>
